Workbook

Sheet Index
A1: Asia Eateries - Singapore, Malaysia, Thailand
A3: Tab | B3: What's in it | C3: Records
A4: Master List | B4: Everything in one filterable table. | C4: =COUNTA('Master List'!$G$2:$G$1256)
A5: SG · Omakase & Japanese | B5: Sushi, kappo, kaiseki, yakitori and modern Japanese counters. | C5: =COUNTA('SG · Omakase & Japanese'!$C$2:$C$53)
A6: SG · Noodles & Hawker | B6: Bak chor mee, wanton, prawn mee, laksa, fishball, beef, fried kway teow, Hokkien mee. | C6: =COUNTA('SG · Noodles & Hawker'!$C$2:$C$34)
A7: SG · Rice, Soup & Porridge | B7: Chicken rice, claypot rice, bak kut teh, fish soup, soups, congee, kway chap, yong tau foo. | C7: =COUNTA('SG · Rice, Soup & Porridge'!$C$2:$C$39)
A8: SG · Zi Char & Seafood | B8: Cooked food / zi char, Chinese restaurants and seafood. | C8: =COUNTA('SG · Zi Char & Seafood'!$C$2:$C$35)
A9: SG · Indian, Malay & Peranakan | B9: Indian, biryani, nasi lemak, Malay and Peranakan. | C9: =COUNTA('SG · Indian, Malay & Peranakan'!$C$2:$C$14)
A10: SG · Snacks, Kueh & Sides | B10: Oyster omelette, carrot cake, curry puffs, kueh, patisserie, tea. | C10: =COUNTA('SG · Snacks, Kueh & Sides'!$C$2:$C$14)
A11: SG · International & Western | B11: Italian, Spanish, French, Thai, Korean, steakhouses, modern Singaporean. | C11: =COUNTA('SG · International & Western'!$C$2:$C$71)
A12: MY · Fine Dining & Japanese | B12: Omakase counters across KL, Penang and JB. | C12: =COUNTA('MY · Fine Dining & Japanese'!$C$2:$C$31)
A13: MY · Modern & Western | B13: MICHELIN-starred and Selected modern Malaysian, European and steakhouses. | C13: =COUNTA('MY · Modern & Western'!$C$2:$C$80)
A14: MY · Noodles Egg & Pan Mee | B14: Wantan mee, pan mee / ban mian, pork noodles, hakka, fishball. | C14: =COUNTA('MY · Noodles Egg & Pan Mee'!$C$2:$C$163)
A15: MY · Noodles Fried & Wok | B15: Char kuey teow, Hokkien mee, fried rice. | C15: =COUNTA('MY · Noodles Fried & Wok'!$C$2:$C$103)
A16: MY · Noodles Soup & Laksa | B16: Curry mee, assam and Sarawak laksa, prawn, beef, fish head, koay teow th'ng. | C16: =COUNTA('MY · Noodles Soup & Laksa'!$C$2:$C$172)
A17: MY · Rice, Claypot & Congee | B17: Chicken rice, claypot, nasi lemak, congee. | C17: =COUNTA('MY · Rice, Claypot & Congee'!$C$2:$C$96)
A18: MY · Bak Kut Teh | B18: Bak kut teh, dry and soup. | C18: =COUNTA('MY · Bak Kut Teh'!$C$2:$C$39)
A19: MY · Seafood & Hotpot | B19: Steamed fish head, hotpot, seafood restaurants. | C19: =COUNTA('MY · Seafood & Hotpot'!$C$2:$C$42)
A20: MY · Roast Duck & Yong Tau Foo | B20: Roast and Teochew stewed duck, yong tau foo. | C20: =COUNTA('MY · Roast Duck & Yong Tau Foo'!$C$2:$C$33)
A21: MY · Peranakan & Malay | B21: Nyonya, Baba and Malay kitchens. | C21: =COUNTA('MY · Peranakan & Malay'!$C$2:$C$27)
A22: MY · Indian & South Asian | B22: Indian, Sri Lankan and South Asian. | C22: =COUNTA('MY · Indian & South Asian'!$C$2:$C$28)
A23: MY · Tai Chow & Kopitiam | B23: Tai chow spots and kopitiam / street hawker fare. | C23: =COUNTA('MY · Tai Chow & Kopitiam'!$C$2:$C$169)
A24: MY · Snacks, Kueh & Desserts | B24: Nyonya kueh, apom, pancakes and sweets. | C24: =COUNTA('MY · Snacks, Kueh & Desserts'!$C$2:$C$10)
A25: MY · Bars & Cocktails | B25: Asia's 50 Best Bars entries. | C25: =COUNTA('MY · Bars & Cocktails'!$C$2:$C$3)
A26: TH · Bangkok | B26: Bangkok noodles, Isaan, Thai-Chinese, seafood, bars and dessert. | C26: =COUNTA('TH · Bangkok'!$C$2:$C$20)
A27: Other · Travel & Unplaced | B27: Entries whose city could not be confirmed. | C27: =COUNTA('Other · Travel & Unplaced'!$C$2:$C$2)
A28: TOTAL (tabs) | C28: =SUM(C5:C27)

Sheet Master List
A1: # | B1: Source | C1: Country | D1: City / State | E1: Food Type Category | F1: Cuisine / Style | G1: Name | H1: Area / Location | I1: Address | J1: Phone | K1: Typical Hours | L1: Accolades | M1: Price Guide (per pax) | N1: Instagram / Web | O1: What To Order / Signature | P1: Google Rating | Q1: Notes
A2: 1 | B2: Curated (verified) | C2: Singapore | D2: Singapore | E2: Japanese - Sushi Omakase | F2: Edomae sushi omakase | G2: Shoukouwa | H2: One Fullerton / Marina Bay | I2: 1 Fullerton Rd, #02-02A One Fullerton, Singapore 049213 | J2: +65 6423 9939 | K2: Tue-Sat 12:30-15:00, 18:00-22:30; Sun-Mon closed | L2: Two MICHELIN stars | M2: S$400-700+ | N2: shoukouwa.com.sg | O2: Pristine Edomae nigiri course; rare seasonal white fish | P2: 4.5 | Q2: Eight-seat hinoki counter overlooking Marina Bay. Ten years in operation. Fish flown from Toyosu.
A3: 2 | B3: Curated (verified) | C3: Singapore | D3: Singapore | E3: Japanese - Sushi Omakase | F3: Edomae sushi omakase | G3: Sushi Sakuta | H3: Millenia Walk | I3: 9 Raffles Blvd, #01-06/07/08 Millenia Walk, Singapore 039596 | J3: +65 9863 9302 | K3: Tue-Sun 12:30-15:00, 19:00-22:30 (Thu dinner only); Mon closed | L3: Two MICHELIN stars | M3: S$400-700+ | N3: - | O3: Seasonal nigiri course built entirely on Japanese fish | P3: 4.8 | Q3: Chef Yoshio Sakuta. Five-metre hinoki counter, 8 seats - book roughly a month ahead. Relocated from Kempinski.
A4: 3 | B4: Curated (verified) | C4: Singapore | D4: Singapore | E4: Japanese - Sushi Kappo | F4: Edomae sushi + seasonal kappo | G4: Hamamoto | H4: Tras Street / Tanjong Pagar | I4: 58 Tras St, Singapore 078997 | J4: +65 9672 7110 | K4: Tue-Sat 12:00-15:00, 18:30-23:00; Sun-Mon closed | L4: One MICHELIN star | M4: S$300-500 | N4: - | O4: Ise ebi and Yoichi murasaki uni with kaluga caviar | P4: 4.9 | Q4: Chef Kazuhiro Hamamoto (Kyoto). Singapore's only curved hinoki counter, 12 seats. Hard to book.
A5: 4 | B5: Curated (verified) | C5: Singapore | D5: Singapore | E5: Japanese - Sushi Omakase | F5: Edomae sushi omakase | G5: Shinji by Kanesaka | H5: Bras Basah / Carlton Hotel | I5: 76 Bras Basah Rd, Singapore 189558 | J5: +65 6338 6131 | K5: Lunch and dinner seatings; confirm on booking | L5: One MICHELIN star | M5: S$200-400+ | N5: shinjibykanesaka.com | O5: 15-piece sushi set (approx. S$200++); Yume omakase | P5: 4.6 | Q5: Ginza Kanesaka lineage, in Singapore since 2010 - one of the longest-standing omakase counters here. A second outpost operates at The St. Regis.
A6: 5 | B6: Curated (verified) | C6: Singapore | D6: Singapore | E6: Japanese - Sushi Omakase | F6: Edomae sushi omakase | G6: Ginza Sushi Ichi | H6: Orchard / Marriott Tang Plaza | I6: 320 Orchard Rd, #01-04 Singapore Marriott Tang Plaza Hotel, Singapore 238865 | J6: +65 6235 5514 | K6: Tue-Sun 12:00-14:30, 18:00-22:30; Mon closed | L6: One MICHELIN star (retained a decade) | M6: S$200-450 | N6: - | O6: Botan lunch omakase; smoked tuna cheek; seasonal hamaguri clam | P6: 4.6 | Q6: Otoro only appears on the higher-priced menus. Private room available.
A7: 6 | B7: Curated (verified) | C7: Singapore | D7: Singapore | E7: Japanese - Sushi Omakase | F7: Edomae sushi omakase | G7: Sushi Kimura Plus | H7: Cuscaden Road / Conrad Singapore | I7: 1 Cuscaden Rd, #01-03 Conrad, Singapore 249715 | J7: +65 8977 5027 | K7: Tue-Sun, lunch 12:30-14:30 and dinner 19:00-21:30 (varies by day); Mon closed | L7: Chef held one MICHELIN star at previous restaurant | M7: S$380 dinner set | N7: - | O7: Spear-hunted fish; Yura uni; ankimo | P7: 4.7 | Q7: Chef Tomoo Kimura's return after the original Sushi Kimura at Palais Renaissance closed in 2024. Eight seats, every piece made by the chef himself. Rice recipe now less sweet.
A8: 7 | B8: Curated (verified) | C8: Singapore | D8: Singapore | E8: Japanese - Sushi Omakase | F8: Edomae sushi omakase | G8: Sushi Ayumu by Masa Ishibashi | H8: Mandarin Gallery / Orchard | I8: 333A Orchard Rd, #04-16 Mandarin Gallery, Singapore 238897 | J8: +65 9159 0102 | K8: Tue-Sun 12:00-15:00, 18:30-22:30; Mon closed | L8: MICHELIN Guide listed | M8: S$250-450 | N8: - | O8: Chef's premium selection; flamed toro nigiri | P8: 4.6 | Q8: Extensive sake and wine list.
A9: 8 | B9: Curated (verified) | C9: Singapore | D9: Singapore | E9: Japanese - Sushi Omakase | F9: Edomae sushi omakase | G9: Sushi Mitsuya | H9: Tras Street / Tanjong Pagar | I9: 60 Tras St, #01-01, Singapore 078999 | J9: +65 6438 2608 | K9: Lunch and dinner; confirm on booking | L9: MICHELIN Guide listed | M9: From S$130 (Umi) to S$300+ | N9: - | O9: Umi omakase; seasonal and unusual fish selection | P9: 4.4 | Q9: Open over a decade. Reservations can need a month's lead time. Menu was revised recently - recent reviews are mixed.
A10: 9 | B10: Curated (verified) | C10: Singapore | D10: Singapore | E10: Japanese - Sushi Omakase | F10: Edomae sushi omakase | G10: Sushi Sato | H10: Dempsey Hill | I10: 6B Dempsey Rd, Singapore 247662 | J10: +65 8380 3830 | K10: Tue-Sun 12:00-15:00, 18:30-22:30; Mon closed | L10: MICHELIN Guide listed | M10: S$250-450 | N10: - | O10: Seared baby tuna with uni; grilled rock fish with mountain yam | P10: 4.9 | Q10: Nine-seat counter, quiet end of Dempsey. Chef Sato is personable. Note Chef Kawana has departed.
A11: 10 | B11: Curated (verified) | C11: Singapore | D11: Singapore | E11: Japanese - Sushi Kappo | F11: Kappo omakase | G11: Nishikane | H11: Tras Street / Tanjong Pagar | I11: 78 Tras St, #01-01, Singapore 079017 | J11: +65 9179 4355 | K11: Mon-Sat 12:00-14:00, 18:00-22:30; Sun closed | L11: MICHELIN Guide listed | M11: S$250-450 | N11: - | O11: Seasonal themed degustation; uni; Omi beef; ice-bowl somen | P11: 4.8 | Q11: Chef Nobuhiro Nishi. Highly theatrical, seasonal presentation - Kyoto sensibility.
A12: 11 | B12: Curated (verified) | C12: Singapore | D12: Singapore | E12: Japanese - Sushi Omakase | F12: Edomae sushi omakase | G12: Sushi Masa by Ki-setsu | H12: Cuppage Plaza / Orchard | I12: 5 Koek Rd, #06-03 Cuppage Plaza, Singapore 228796 | J12: +65 9752 5851 | K12: Tue-Sat 19:00-22:00; Sun-Mon closed | L12: Widely rated among Singapore's best value counters | M12: From S$230 (Hotaru, 16+ courses) | N12: - | O12: Anago; negitoro monaka; otoro aburi; add-on scallop | P12: 4.9 | Q12: Eight seats, hidden inside an ageing Orchard mall. The 'Hiseki' menu is private bookings or Sundays only, roughly three weeks' notice.
A13: 12 | B13: Curated (verified) | C13: Singapore | D13: Singapore | E13: Japanese - Sushi Omakase | F13: Edomae sushi omakase | G13: Sushi Muni | H13: International Plaza / Tanjong Pagar | I13: 10 Anson Rd, #02-28 International Plaza, Singapore 079903 | J13: +65 8492 6387 | K13: Mon-Sat, lunch 12:00-14:30 and dinner 18:00-22:00 (Mon dinner only); Sun closed | L13: - | M13: Approx. S$200++ dinner | N13: - | O13: Muni omakase; off-menu uni ice cream | P13: 4.9 | Q13: Chef Chon (ex-Miraku). No soy sauce for dipping - each piece is finished by the chef. Pick your own sake cup by zodiac sign.
... A38: 37 | B38: Curated (verified) | C38: Malaysia | D38: Kuala Lumpur | E38: Japanese - Sushi Omakase | F38: Edomae sushi omakase | G38: Sushi Ryu | H38: Platinum Park / KLCC | I38: Unit 3.3, Level 2, Platinum Park Tower 1, 11 Persiaran KLCC, 50088 Kuala Lumpur | J38: +60 3-2181 1533 | K38: Mon-Sat 12:00-15:00, 18:00-22:30; Sun closed | L38: Often cited as best value omakase in KL | M38: Lunch from RM279; dinner 'Sakura' from RM579 | N38: - | O38: Prawn sushi topped with foie gras; sake pairings | P38: 4.7 | Q38: Produce flown in Tuesday and Friday. Contemporary sushiya - truffle, caviar and wagyu alongside Japanese seafood.
A39: 38 | B39: Curated (verified) | C39: Malaysia | D39: Kuala Lumpur | E39: Japanese - Sushi Omakase | F39: Sushi omakase | G39: Manten Omakase | H39: Star Residences / Jalan Yap Kwan Seng | I39: Level 88, Tower 2 Rooftop, Star Residence, 1 Jalan Yap Kwan Seng, 53300 Kuala Lumpur | J39: +60 16-755 2200 | K39: Daily 11:30-14:30, 18:00-22:30 | L39: - | M39: Mid to upper range; Tsuyu menu | N39: 4.8 | O39: - | P39: Uni with ikura; seasonal ingredients flown from Japan | Q39: 4.8
A40: 39 | B40: Curated (verified) | C40: Malaysia | D40: Kuala Lumpur | E40: Japanese - Sushi Omakase | F40: Sushi omakase (halal-friendly) | G40: Kinome | H40: Lot 10 / Isetan The Japan Store | I40: 4th Floor, Isetan The Japan Store, Lot 10, 50 Jln Sultan Ismail, Bukit Bintang, 50520 Kuala Lumpur | J40: +60 12-320 4238 | K40: Daily 12:00-15:00, 18:00-23:00 | L40: - | M40: 'Kinome' 18-course set approx. RM398++ | N40: - | O40: 18-course omakase; fresh nigiri; Lot 10 Japanese cheesecake as dessert | P40: 4.9 | Q40: Reported to be fully halal - useful for mixed groups. Book ahead.
A41: 40 | B41: Curated (verified) | C41: Malaysia | D41: Kuala Lumpur | E41: Japanese - Sushi Omakase | F41: Edomae sushi omakase | G41: EDJU Omakase | H41: Damansara City Mall / Pusat Bandar Damansara | I41: G-19, Ground Floor, Damansara City Mall, 6 Jalan Damanlela, 50490 Kuala Lumpur | J41: +60 12-301 3060 | K41: Confirm on booking | L41: - | M41: Premium omakase; 20-piece sushi set approx. RM430++ | N41: @ed.ju_restaurant | O41: Edomae-style sushi and dessert course | P41: 4.3 | Q41: Reopened after a long renovation with a Michelin-experienced Japanese chef. Reviews on value are mixed - be clear about add-ons before ordering.
A42: 41 | B42: Curated (verified) | C42: Malaysia | D42: Kuala Lumpur | E42: Japanese - Multi-concept | F42: Omakase, teppanyaki, sushi counter | G42: Hanare Japanese Restaurant | H42: The Intermark / Jalan Tun Razak | I42: Vista Tower, 182 Jln Tun Razak, Kampung Datuk Keramat, 50400 Kuala Lumpur | J42: +60 12-286 0210 | K42: Confirm on booking | L42: - | M42: RM380++ omakase; weekend a la carte brunch | N42: - | O42: Omakase menu; chutoro and oysters from Toyosu; wagyu | P42: 4.4 | Q42: Sushi counter, bar, teppanyaki seating and private rooms. Menu changes seasonally. Accommodating for elderly guests and larger groups.
A43: 42 | B43: Curated (verified) | C43: Malaysia | D43: Kuala Lumpur | E43: Japanese - Modern | F43: Progressive Japanese tasting menu | G43: Kikubari | H43: Damansara City Mall / Pusat Bandar Damansara | I43: L3-01A, Damansara City Mall, Jalan Damanlela, Pusat Bandar Damansara, 50490 Kuala Lumpur | J43: +60 13-362 4546 | K43: Confirm on booking | L43: Award-winning progressive Japanese | M43: Signature tasting menu | N43: - | O43: Signature tasting menu; fruit tomato amela; strong vegetarian options | P43: 4.2 | Q43: French-Japanese, tapas-style rather than classical omakase. Rooftop of DC Mall with Japanese sand-art floor. Confirm signature dishes are available.
A44: 43 | B44: Curated (verified) | C44: Malaysia | D44: Kuala Lumpur | E44: Japanese - Modern | F44: Nobu-style Japanese-Peruvian | G44: Nobu Kuala Lumpur | H44: Four Seasons Place / Jalan Ampang | I44: L4A-05, Level 4A, Shoppes at Four Seasons Place, 145 Jln Ampang, 50450 Kuala Lumpur | J44: +60 3-2380 0028 | K44: Daily 11:45-14:00, 18:00-22:00 | L44: International Nobu group | M44: RM400-800 | N44: - | O44: Yellowtail jalapeno; new-style sashimi; black cod; omakase on request | P44: 4 | Q44: Creative rather than purist. Portions run small for the price. Request a window table.
A45: 44 | B45: Curated (verified) | C45: Malaysia | D45: Kuala Lumpur | E45: Japanese - Multi-concept | F45: Japanese fine dining, teppanyaki, sushi | G45: Iketeru | H45: Hilton Kuala Lumpur / KL Sentral | I45: Level 8, Hilton Kuala Lumpur, 3 Jalan Stesen Sentral, 50470 Kuala Lumpur | J45: +60 3-2264 2264 | K45: Daily 12:00-14:30, 18:30-22:30 | L45: Long-standing KL institution | M45: RM250-600 | N45: - | O45: Teppanyaki counter; unagi set; sashimi platters | P45: 4.5 | Q45: Reliable for business entertaining and larger tables rather than a pure omakase counter.
A46: 45 | B46: Curated (verified) | C46: Malaysia | D46: Kuala Lumpur | E46: Japanese - Modern | F46: Set menus with skyline views | G46: UMI Japanese Restaurant | H46: Imperial Lexis KL / Jalan Kia Peng | I46: Level 52, Imperial Lexis Kuala Lumpur, 15 Jalan Kia Peng, 50450 Kuala Lumpur | J46: +60 3-2177 1188 | K46: Mon-Sat 12:00-15:00, 18:00-23:00; Sun closed | L46: - | M46: RM250-500 | N46: - | O46: Seasonal set menus; chawanmushi with caviar; black cod with yuzu teriyaki | P46: 4.7 | Q46: 52nd floor with KLCC and KL Tower views. Corkage applies for outside cakes. Sky deck is residents-only.
A47: 46 | B47: Curated (verified) | C47: Malaysia | D47: Penang | E47: Japanese - Sushi Omakase | F47: Seasonal sushi omakase | G47: Kaishin Sushi Omakase | H47: George Town | I47: 69 Jalan Sri Bahari, George Town, 10050 Penang | J47: +60 14-228 8069 | K47: Tue-Sun 18:00-22:30; Mon closed | L47: Penang's standout omakase counter | M47: Mid to upper range | N47: - | O47: Seasonal Japanese dishes; nuanced vinegar work in the shari | P47: 4.9 | Q47: Small, discreet signage. Generous portions by omakase standards. Ingredients sourced directly from Japan.
A48: 47 | B48: Curated (verified) | C48: Malaysia | D48: Johor Bahru | E48: Japanese - Sushi Omakase | F48: Sushi omakase | G48: Kamii Sushi Omakase | H48: Eco Palladium / Taman Ekoflora | I48: 02-17, Block A, Pusat Perdagangan Ekoflora, Jln Ekoflora 7/3, Taman Ekoflora, 81100 Johor Bahru | J48: +60 18-461 1132 | K48: Tue-Sun 18:00-23:00; Mon closed | L48: Leading JB counter | M48: Mid range - strong value vs Singapore | N48: - | O48: Seasonal nigiri; yuzu radish; well-seasoned shari | P48: 4.9 | Q48: Black-and-gold modern room, counter seating. Reserve ahead. A practical option when crossing from Singapore.
A49: 48 | B49: Curated (verified) | C49: Thailand | D49: Bangkok | E49: Noodles - Beef | F49: Beef hotpot + beef noodles | G49: Heng Chun Seng | H49: Khlong Toei | I49: 133 Sunthonkosa Rd, Khlong Toei, Bangkok 10110 | J49: +66 97 017 7949 | K49: Mon-Tue 07:20-20:30; Wed-Sun 07:20-16:00 | L49: - | M49: Budget | N49: - | O49: Beef hotpot - order all the different cuts; beef tongue; braised shank; pork satay while waiting | P49: 4.6 | Q49: Traditional charcoal stoves. Long but fast-moving queue.
A50: 49 | B50: Curated (verified) | C50: Thailand | D50: Bangkok | E50: Noodles - Boat Noodles | F50: Boat noodles (kuay teow ruea) | G50: Toy Kuay Teow Ruea (Boat Noodles) | H50: Victory Monument / Ratchathewi | I50: Soi Ratchawithi 18, Thung Phaya Thai, Ratchathewi, Bangkok 10400 | J50: +66 81 619 1925 | K50: Daily 08:00-17:00 | L50: - | M50: From ~15 THB a bowl | N50: - | O50: The rich, earthy, spicy broth - order 4-6 small bowls; deep-fried pork skin | P50: 4.4 | Q50: Choose pork or beef, nam tok or tom yum, with or without soup. Cheapest around Victory Monument.
A51: 50 | B51: Curated (verified) | C51: Thailand | D51: Bangkok | E51: Noodles - Tom Yum | F51: Sukhothai-style noodles | G51: Ta Chai Sukhothai Noodles | H51: Old Town / Giant Swing | I51: 119/1 Thanon Bamrung Mueang, Sao Chingcha, Phra Nakhon, Bangkok 10200 | J51: +66 81 564 1497 | K51: Mon-Fri 06:00-13:30; Sat 06:00-14:00; Sun closed | L51: - | M51: Approx. 60 THB large bowl | N51: - | O51: Tom yum bamee haeng (dry egg noodle tom yum) with BBQ pork, long beans, crushed peanuts | P51: 4.5 | Q51: Superb tomyum noodles - specify non-spicy when ordering if needed.
... A81: 80 | B81: Curated (verified) | C81: Malaysia | D81: Kuala Lumpur | E81: Chinese - Seafood | F81: Claypot river fish, Guangxi-style seafood | G81: Xian Yu Xian Seafood Restaurant | H81: Taman Usahawan Kepong | I81: 37, Jalan Metro Perdana Timur 3, Taman Usahawan Kepong, 52100 Kuala Lumpur | J81: +60 12-988 1358 | K81: Daily 12:00-15:00, 17:00-22:00 | L81: - | M81: Approx. RM240 for a table of dishes | N81: - | O81: Claypot river red-tail catfish; pork belly sang mee; claypot water spinach; salted egg pork belly | P81: 4 | Q81: Bukit Tinggi-style claypot fish brought to Kepong - the kitchen promises to replace any fish that tastes muddy. Book ahead; parking fills by 19:00. Room is noisy.
A82: 81 | B82: MICHELIN / web guides (Jul 2026) | C82: Singapore | D82: Singapore | E82: SG Fish Soup & Fish Head | F82: Singapore hawker / local | G82: Boon Keng Road Fish Head Bee Hoon | H82: Bedok North | I82: 416 Bedok North Avenue 2, #01-53, Singapore 460416 | J82: - | K82: Daily 10:00-22:00 | L82: MICHELIN Bib Gourmand 2026 - NEW 2026 | M82: - | N82: - | O82: - | Q82: MICHELIN Guide Singapore Bib Gourmand 2026 (new entry). Despite the name it is in Bedok North, not Boon Keng. Also does poached or fried fish slices. Address and hours per DanielFoodDiary (@danielfooddiary), 28 July 2026.
A83: 82 | B83: MICHELIN / web guides (Jul 2026) | C83: Singapore | D83: Singapore | E83: SG Oyster Omelette & Carrot Cake | F83: Singapore hawker / local | G83: Hup Kee Fried Oyster Omelette | H83: Newton Food Centre | I83: 500 Clemenceau Avenue North, #01-73 Newton Food Centre, Singapore 229495 | J83: - | K83: Wed-Sat 17:30-00:00; Sun-Tue closed | L83: MICHELIN Bib Gourmand 2026 - NEW 2026 | M83: - | N83: - | O83: - | Q83: MICHELIN Guide Singapore Bib Gourmand 2026 (new entry). Started as a street stall. Address and hours per DanielFoodDiary (@danielfooddiary), 28 July 2026.
A84: 83 | B84: MICHELIN / web guides (Jul 2026) | C84: Singapore | D84: Singapore | E84: SG Hawker - Other | F84: Singapore hawker / local | G84: Jia Xiang | H84: - | I84: - | J84: - | K84: - | L84: MICHELIN Bib Gourmand 2026 - NEW 2026 | M84: - | N84: - | O84: - | Q84: MICHELIN Guide Singapore Bib Gourmand 2026 (97 establishments). Category inferred from the establishment name; address, phone and hours not yet verified.
A85: 84 | B85: MICHELIN / web guides (Jul 2026) | C85: Singapore | D85: Singapore | E85: SG Noodles - Laksa | F85: Singapore hawker / local | G85: King of Laksa | H85: - | I85: - | J85: - | K85: - | L85: MICHELIN Bib Gourmand 2026 - NEW 2026 | M85: - | N85: - | O85: - | Q85: MICHELIN Guide Singapore Bib Gourmand 2026 (97 establishments). Category inferred from the establishment name; address, phone and hours not yet verified.
A86: 85 | B86: MICHELIN / web guides (Jul 2026) | C86: Singapore | D86: Singapore | E86: SG Indian | F86: Singapore hawker / local | G86: Rajarani Thosai | H86: - | I86: - | J86: - | K86: - | L86: MICHELIN Bib Gourmand 2026 - NEW 2026 | M86: - | N86: - | O86: - | Q86: MICHELIN Guide Singapore Bib Gourmand 2026 (97 establishments). Category inferred from the establishment name; address, phone and hours not yet verified.
A87: 86 | B87: MICHELIN / web guides (Jul 2026) | C87: Singapore | D87: Singapore | E87: SG Soup - Herbal & Mutton | F87: Singapore hawker / local | G87: Seng Kee Black Chicken Herbal Soup | H87: - | I87: - | J87: - | K87: - | L87: MICHELIN Bib Gourmand 2026 - NEW 2026 | M87: - | N87: - | O87: - | Q87: MICHELIN Guide Singapore Bib Gourmand 2026 (97 establishments). Category inferred from the establishment name; address, phone and hours not yet verified.
A88: 87 | B88: MICHELIN / web guides (Jul 2026) | C88: Singapore | D88: Singapore | E88: SG Noodles - Bak Chor Mee | F88: Singapore hawker / local | G88: Tian Nan Xing Minced Pork Noodle | H88: - | I88: - | J88: - | K88: - | L88: MICHELIN Bib Gourmand 2026 - NEW 2026 | M88: - | N88: - | O88: - | Q88: MICHELIN Guide Singapore Bib Gourmand 2026 (97 establishments). Category inferred from the establishment name; address, phone and hours not yet verified.
A89: 88 | B89: MICHELIN / web guides (Jul 2026) | C89: Singapore | D89: Singapore | E89: SG Hawker - Other | F89: Singapore hawker / local | G89: Xiangyee | H89: - | I89: - | J89: - | K89: - | L89: MICHELIN Bib Gourmand 2026 - NEW 2026 | M89: - | N89: - | O89: - | Q89: MICHELIN Guide Singapore Bib Gourmand 2026 (97 establishments). Category inferred from the establishment name; address, phone and hours not yet verified.
A90: 89 | B90: MICHELIN / web guides (Jul 2026) | C90: Singapore | D90: Singapore | E90: SG Yong Tau Foo | F90: Singapore hawker / local | G90: Xiu Ji Ikan Bilis Yong Tau Fu | H90: Chinatown Complex | I90: - | J90: - | K90: - | L90: MICHELIN Bib Gourmand 2026 - NEW 2026 | M90: - | N90: - | O90: - | Q90: MICHELIN Guide Singapore Bib Gourmand 2026 (97 establishments). Category inferred from the establishment name; address, phone and hours not yet verified.
A91: 90 | B91: MICHELIN / web guides (Jul 2026) | C91: Singapore | D91: Singapore | E91: SG Kway Chap & Braised Duck | F91: Singapore hawker / local | G91: Yi Pin Wei Braised Duck Kway Chap | H91: - | I91: - | J91: - | K91: - | L91: MICHELIN Bib Gourmand 2026 - NEW 2026 | M91: - | N91: - | O91: - | Q91: MICHELIN Guide Singapore Bib Gourmand 2026 (97 establishments). Category inferred from the establishment name; address, phone and hours not yet verified.
A92: 91 | B92: MICHELIN / web guides (Jul 2026) | C92: Singapore | D92: Singapore | E92: SG Noodles - Bak Chor Mee | F92: Singapore hawker / local | G92: A Noodle Story | H92: Amoy Street Food Centre | I92: - | J92: - | K92: - | L92: MICHELIN Bib Gourmand 2026 - 10-edition stalwart | M92: - | N92: - | O92: - | Q92: MICHELIN Guide Singapore Bib Gourmand 2026 (97 establishments). Category inferred from the establishment name; address, phone and hours not yet verified.
A93: 92 | B93: MICHELIN / web guides (Jul 2026) | C93: Singapore | D93: Singapore | E93: SG Noodles - Prawn Mee | F93: Singapore hawker / local | G93: Adam Road Noo Cheng Big Prawn Noodle | H93: Adam Road Food Centre | I93: - | J93: - | K93: - | L93: MICHELIN Bib Gourmand 2026 | M93: - | N93: - | O93: - | Q93: MICHELIN Guide Singapore Bib Gourmand 2026 (97 establishments). Category inferred from the establishment name; address, phone and hours not yet verified.
...

Sheet SG · Omakase & Japanese
A1: # | B1: Food Type Category | C1: Name | D1: City / State | E1: Area / Location | F1: Address | G1: Phone | H1: Typical Hours | I1: Accolades | J1: Price Guide (per pax) | K1: Instagram / Web | L1: What To Order / Signature | M1: Google Rating | N1: Source | O1: Notes
A2: 1 | B2: Japanese - Kappo | C2: 7s Kappo | D2: Singapore | E2: - | F2: - | G2: - | H2: - | I2: - | J2: - | K2: - | L2: - | N2: Omakase Diaries (Google Drive) | O2: From the 'Omakase Diaries' folder in Google Drive (one subfolder per meal). Country and food type were inferred from the folder name; details not verified unless shown.
A3: 2 | B3: Japanese - Kappo | C3: Hachi Restaurant | D3: Singapore | E3: Keppel South Central / Tanjong Pagar | F3: 10 Hoe Chiang Rd, #01-07 Keppel South Central, Singapore 089315 | G3: +65 6734 9622 | H3: Mon-Sat 12:00-14:30, 18:00-23:00; Sun closed | I3: - | J3: S$200-400; sake pairing add-on approx. S$38 | K3: - | L3: Shiki seasonal omakase; chutoro with pinenut-anchovy dressing; A5 wagyu yakimono | M3: 4.6 | N3: Curated (verified) | O3: Also a strong set-lunch option (kaisen chirashi-don, wagyu souryu don).
A4: 3 | B4: Japanese - Kappo | C4: Kei Hachi | D4: Singapore | E4: - | F4: 8 Keong Saik Rd., Singapore 089116 | G4: +65 6518 4755 | H4: Confirm on booking | I4: - | J4: - | K4: - | L4: - | M4: 4.3 | N4: Omakase Diaries (Google Drive) | O4: From the 'Omakase Diaries' folder in Google Drive (one subfolder per meal). Country and food type were inferred from the folder name; details not verified unless shown. Verified via Google Places, 29 July 2026.
A5: 4 | B5: Japanese - Kappo | C5: Ki-sho | D5: Singapore | E5: Scotts Road | F5: 29 Scotts Rd, Singapore 228224 | G5: +65 9061 6109 | H5: Mon-Fri 12:00-15:00, 18:30-23:00; Sat dinner only; Sun closed | I5: MICHELIN Guide listed | J5: 6-9 courses, S$160-360; dinner kappou S$280-360++ | K5: - | L5: Tottori Wagyu smoked over hay; Zen Garden platter; seasonal dashi | M5: 4.6 | N5: Curated (verified) | O5: Chef Taro Takayama, formerly private chef to Japan's ambassador to Singapore. Black-and-white colonial bungalow. Nearest MRT Newton.
A6: 5 | B6: Japanese - Kappo | C6: Tsubaki by Shunsui | D6: Singapore | E6: Cuppage Plaza / Orchard | F6: 5 Koek Rd, #04-02 Cuppage Plaza, Singapore 228796 | G6: +65 9772 4300 | H6: Dinner service; confirm on booking | I6: MICHELIN Guide listed | J6: 7 or 9 course sets | K6: - | L6: Wagyu and uni; giant squid tempura; donabe rice | M6: 4.6 | N6: Curated (verified) | O6: Chef Kenta. No signboard - discreet entrance. Wide sake selection, so avoid driving.
A7: 6 | B7: Japanese - Kappo | C7: WA Kappou | D7: Singapore | E7: Keong Saik Road | F7: 27 Keong Saik Rd., Singapore 089134 | G7: +65 9610 8353 | H7: Daily 12:00-15:00, 18:00-22:30 | I7: - | J7: S$150-300 | K7: - | L7: Seasonal sashimi; wagyu course | M7: 4.9 | N7: Curated (verified) | O7: Small counter, modern kappo. Chefs engage without being intrusive.
A8: 7 | B8: Japanese - Modern | C8: Hazu | D8: Singapore | E8: - | F8: - | G8: - | H8: - | I8: - | J8: - | K8: - | L8: - | N8: Omakase Diaries (Google Drive) | O8: From the 'Omakase Diaries' folder in Google Drive (one subfolder per meal). Country and food type were inferred from the folder name; details not verified unless shown.
A9: 8 | B9: Japanese - Modern | C9: Kamoshita | D9: Singapore | E9: - | F9: - | G9: - | H9: - | I9: - | J9: - | K9: - | L9: - | N9: Omakase Diaries (Google Drive) | O9: From the 'Omakase Diaries' folder in Google Drive (one subfolder per meal). Country and food type were inferred from the folder name; details not verified unless shown.
A10: 9 | B10: Japanese - Modern | C10: Kott-Don by Flower Pig | D10: Singapore | E10: - | F10: - | G10: - | H10: - | I10: - | J10: - | K10: - | L10: - | N10: Omakase Diaries (Google Drive) | O10: From the 'Omakase Diaries' folder in Google Drive (one subfolder per meal). Country and food type were inferred from the folder name; details not verified unless shown.
A11: 10 | B11: Japanese - Modern | C11: Mizuya, Tras Street | D11: Singapore | E11: - | F11: - | G11: - | H11: - | I11: - | J11: - | K11: - | L11: - | N11: Omakase Diaries (Google Drive) | O11: From the 'Omakase Diaries' folder in Google Drive (one subfolder per meal). Country and food type were inferred from the folder name; details not verified unless shown.
A12: 11 | B12: Japanese - Modern | C12: Sanpoutei Ramen | D12: Singapore | E12: - | F12: - | G12: - | H12: - | I12: - | J12: - | K12: - | L12: - | N12: Omakase Diaries (Google Drive) | O12: From the 'Omakase Diaries' folder in Google Drive (one subfolder per meal). Country and food type were inferred from the folder name; details not verified unless shown.
A13: 12 | B13: Japanese - Modern | C13: Sen of Japan | D13: Singapore | E13: - | F13: - | G13: - | H13: - | I13: - | J13: - | K13: - | L13: - | N13: Omakase Diaries (Google Drive) | O13: From the 'Omakase Diaries' folder in Google Drive (one subfolder per meal). Country and food type were inferred from the folder name; details not verified unless shown.
A14: 13 | B14: Japanese - Modern | C14: Sushi Tei | D14: Singapore | E14: - | F14: - | G14: - | H14: - | I14: - | J14: - | K14: - | L14: - | N14: Omakase Diaries (Google Drive) | O14: From the 'Omakase Diaries' folder in Google Drive (one subfolder per meal). Country and food type were inferred from the folder name; details not verified unless shown.
A15: 14 | B15: Japanese - Modern | C15: Suzuki, The Mondrian | D15: Singapore | E15: - | F15: - | G15: - | H15: - | I15: - | J15: - | K15: - | L15: - | N15: Omakase Diaries (Google Drive) | O15: From the 'Omakase Diaries' folder in Google Drive (one subfolder per meal). Country and food type were inferred from the folder name; details not verified unless shown.
A16: 15 | B16: Japanese - Modern | C16: Tamashii | D16: Singapore | E16: - | F16: - | G16: - | H16: - | I16: - | J16: - | K16: - | L16: - | N16: Omakase Diaries (Google Drive) | O16: From the 'Omakase Diaries' folder in Google Drive (one subfolder per meal). Country and food type were inferred from the folder name; details not verified unless shown.
A17: 16 | B17: Japanese - Modern | C17: Waku Ghin | D17: Singapore | E17: The Shoppes at Marina Bay Sands | F17: 10 Bayfront Ave, #02-03 The Shoppes, Marina Bay Sands, Singapore 018956 | G17: +65 6688 8507 | H17: Daily 17:00-23:00 | I17: MICHELIN-starred, Chef Tetsuya Wakuda | J17: S$500+ | K17: - | L17: Island lobster with caviar; grilled wagyu on rice; bara-chirashi | M17: 4.3 | N17: Curated (verified) | O17: Japanese-European degustation rather than pure omakase. Multi-room progressive format.
A18: 17 | B18: Japanese - Modern | C18: Wakuda | D18: Singapore | E18: Marina Bay Sands | F18: 10 Bayfront Ave, Marina Bay Sands Hotel Tower 2 Lobby, Singapore 018956 | G18: +65 6688 8885 | H18: Daily 11:30-00:00 | I18: Chef Tetsuya Wakuda | J18: Omakase from approx. S$128 (13-17 courses) | K18: - | L18: Signature omakase; handrolls; Ohmi wagyu; Wakuda Sling at the bar | M18: 4.2 | N18: Curated (verified) | O18: Philosophy of 'shun' - seasonal peak. Ingredients air-flown from Hokkaido, Fukuoka, Shizuoka, Okinawa. Exclusive omakase room. MBS membership unlocks member pricing.
A19: 18 | B19: Japanese - Multi-concept | C19: Keyaki, Pan Pacific | D19: Singapore | E19: - | F19: - | G19: - | H19: - | I19: - | J19: - | K19: - | L19: - | N19: Omakase Diaries (Google Drive) | O19: From the 'Omakase Diaries' folder in Google Drive (one subfolder per meal). Country and food type were inferred from the folder name; details not verified unless shown.
A20: 19 | B20: Japanese - Sushi Kappo | C20: Hamamoto | D20: Singapore | E20: Tras Street / Tanjong Pagar | F20: 58 Tras St, Singapore 078997 | G20: +65 9672 7110 | H20: Tue-Sat 12:00-15:00, 18:30-23:00; Sun-Mon closed | I20: One MICHELIN star | J20: S$300-500 | K20: - | L20: Ise ebi and Yoichi murasaki uni with kaluga caviar | M20: 4.9 | N20: Curated (verified) | O20: Chef Kazuhiro Hamamoto (Kyoto). Singapore's only curved hinoki counter, 12 seats. Hard to book.
A21: 20 | B21: Japanese - Sushi Kappo | C21: Nishikane | D21: Singapore | E21: Tras Street / Tanjong Pagar | F21: 78 Tras St, #01-01, Singapore 079017 | G21: +65 9179 4355 | H21: Mon-Sat 12:00-14:00, 18:00-22:30; Sun closed | I21: MICHELIN Guide listed | J21: S$250-450 | K21: - | L21: Seasonal themed degustation; uni; Omi beef; ice-bowl somen | M21: 4.8 | N21: Curated (verified) | O21: Chef Nobuhiro Nishi. Highly theatrical, seasonal presentation - Kyoto sensibility.
A22: 21 | B22: Japanese - Sushi Omakase | C22: AN Omakase | D22: Singapore | E22: - | F22: 33 Keong Saik Rd., Singapore 089140 | G22: +65 9053 2226 | H22: Daily 12:00-15:00, 18:00-22:30 | I22: - | J22: - | K22: - | L22: - | M22: 4.7 | N22: Omakase Diaries (Google Drive) | O22: From the 'Omakase Diaries' folder in Google Drive (one subfolder per meal). Country and food type were inferred from the folder name; details not verified unless shown. Verified via Google Places, 29 July 2026.
A23: 22 | B23: Japanese - Sushi Omakase | C23: Ashino | D23: Singapore | E23: Club Street / ICON Hotel | F23: 8 Club St, #01-12/13 ICON Hotel, Singapore 069472 | G23: +65 6684 4567 | H23: Mon-Sat, lunch 12:00-14:00 (selected days) and dinner 18:00-22:00; Sun closed | I23: MICHELIN Guide listed | J23: S$200-400 | K23: - | L23: Aged akami and botan ebi; silver-skinned fish; sea salt ice cream with sake | M23: 4.6 | N23: Curated (verified) | O23: Specialist in aged sushi - strongly vinegared shari. Good sake list.
A24: 23 | B24: Japanese - Sushi Omakase | C24: Ginza Sushi Ichi | D24: Singapore | E24: Orchard / Marriott Tang Plaza | F24: 320 Orchard Rd, #01-04 Singapore Marriott Tang Plaza Hotel, Singapore 238865 | G24: +65 6235 5514 | H24: Tue-Sun 12:00-14:30, 18:00-22:30; Mon closed | I24: One MICHELIN star (retained a decade) | J24: S$200-450 | K24: - | L24: Botan lunch omakase; smoked tuna cheek; seasonal hamaguri clam | M24: 4.6 | N24: Curated (verified) | O24: Otoro only appears on the higher-priced menus. Private room available.
A25: 24 | B25: Japanese - Sushi Omakase | C25: Hiryu | D25: Singapore | E25: Telok Ayer Street | F25: 153A Telok Ayer St, Singapore 068610 | G25: +65 6788 9188 | H25: Mon-Sat 12:00-14:30, 18:00-22:30; Sun closed | I25: - | J25: S$200-400 | K25: - | L25: Chutoro, toro, wagyu don with black truffle | M25: 4.5 | N25: Curated (verified) | O25: Chef Raymond Tan. Modern flourishes - caviar, uni, gold leaf.
A26: 25 | B26: Japanese - Sushi Omakase | C26: Ichigo Ichie | D26: Singapore | E26: - | F26: 442 Orchard Rd, #01-16/17 Claymore Connect, Singapore 238879 | G26: +65 9018 2897 | H26: Tue-Sat 12:00-14:30, 19:00-22:30; Sun-Mon closed | I26: - | J26: - | K26: - | L26: - | M26: 4.7 | N26: Omakase Diaries (Google Drive) | O26: From the 'Omakase Diaries' folder in Google Drive (one subfolder per meal). Country and food type were inferred from the folder name; details not verified unless shown. Verified via Google Places, 29 July 2026.
A27: 26 | B27: Japanese - Sushi Omakase | C27: Iyasaka by Hashida | D27: Singapore | E27: Raffles Sentosa | F27: 4 Bukit Manis Rd, Sentosa, Singapore 099947 | G27: +65 8129 5336 | H27: Tue-Sat 19:00-22:30; Sun-Mon closed | I27: - | J27: Approx. S$450++ dinner | K27: - | L27: Ankimo; otoro; belt fish with uni | M27: 5 | N27: Curated (verified) | O27: Chef Kenjiro 'Hatch' Hashida - successor concept to Hashida at Amoy Street. Complimentary valet; restaurant issues a Sentosa entry QR code.
A28: 27 | B28: Japanese - Sushi Omakase | C28: Jisho Omakase | D28: Singapore | E28: - | F28: 35 Robinson Road, #01-03/04 Hotel Telegraph, Singapore 068876 | G28: +65 6980 8030 | H28: Confirm on booking | I28: - | J28: - | K28: - | L28: - | M28: 4.8 | N28: Omakase Diaries (Google Drive) | O28: From the 'Omakase Diaries' folder in Google Drive (one subfolder per meal). Country and food type were inferred from the folder name; details not verified unless shown. Verified via Google Places, 29 July 2026.
A29: 28 | B29: Japanese - Sushi Omakase | C29: Jun Omakase | D29: Singapore | E29: Samsung Hub / Church Street | F29: 3 Church St, #01-01 Samsung Hub, Singapore 049483 | G29: +65 6224 0311 | H29: Mon-Sat 11:30-14:30, 17:30-21:30; Sun closed | I29: - | J29: Accessible - set lunches available | K29: - | L29: Yellowtail don; sashimi plate; omakase counter | M29: 4.5 | N29: Curated (verified) | O29: Popular CBD business-lunch option. Last lunch seating around 14:00.
A30: 29 | B30: Japanese - Sushi Omakase | C30: Mitsu Sushi | D30: Singapore | E30: - | F30: - | G30: - | H30: - | I30: - | J30: - | K30: - | L30: - | N30: Omakase Diaries (Google Drive) | O30: From the 'Omakase Diaries' folder in Google Drive (one subfolder per meal). Country and food type were inferred from the folder name; details not verified unless shown.
A31: 30 | B31: Japanese - Sushi Omakase | C31: Shinji | D31: Singapore | E31: - | F31: - | G31: - | H31: - | I31: - | J31: - | K31: - | L31: - | N31: Omakase Diaries (Google Drive) | O31: From the 'Omakase Diaries' folder in Google Drive (one subfolder per meal). Country and food type were inferred from the folder name; details not verified unless shown.
A32: 31 | B32: Japanese - Sushi Omakase | C32: Shinji by Kanesaka | D32: Singapore | E32: Bras Basah / Carlton Hotel | F32: 76 Bras Basah Rd, Singapore 189558 | G32: +65 6338 6131 | H32: Lunch and dinner seatings; confirm on booking | I32: One MICHELIN star | J32: S$200-400+ | K32: shinjibykanesaka.com | L32: 15-piece sushi set (approx. S$200++); Yume omakase | M32: 4.6 | N32: Curated (verified) | O32: Ginza Kanesaka lineage, in Singapore since 2010 - one of the longest-standing omakase counters here. A second outpost operates at The St. Regis.
A33: 32 | B33: Japanese - Sushi Omakase | C33: Shinzo | D33: Singapore | E33: - | F33: - | G33: - | H33: - | I33: - | J33: - | K33: - | L33: - | N33: Omakase Diaries (Google Drive) | O33: From the 'Omakase Diaries' folder in Google Drive (one subfolder per meal). Country and food type were inferred from the folder name; details not verified unless shown.
A34: 33 | B34: Japanese - Sushi Omakase | C34: Shoukouwa | D34: Singapore | E34: One Fullerton / Marina Bay | F34: 1 Fullerton Rd, #02-02A One Fullerton, Singapore 049213 | G34: +65 6423 9939 | H34: Tue-Sat 12:30-15:00, 18:00-22:30; Sun-Mon closed | I34: Two MICHELIN stars | J34: S$400-700+ | K34: shoukouwa.com.sg | L34: Pristine Edomae nigiri course; rare seasonal white fish | M34: 4.5 | N34: Curated (verified) | O34: Eight-seat hinoki counter overlooking Marina Bay. Ten years in operation. Fish flown from Toyosu.
A35: 34 | B35: Japanese - Sushi Omakase | C35: Sushi Ayumu by Masa Ishibashi | D35: Singapore | E35: Mandarin Gallery / Orchard | F35: 333A Orchard Rd, #04-16 Mandarin Gallery, Singapore 238897 | G35: +65 9159 0102 | H35: Tue-Sun 12:00-15:00, 18:30-22:30; Mon closed | I35: MICHELIN Guide listed | J35: S$250-450 | K35: - | L35: Chef's premium selection; flamed toro nigiri | M35: 4.6 | N35: Curated (verified) | O35: Extensive sake and wine list.
A36: 35 | B36: Japanese - Sushi Omakase | C36: Sushi Jin | D36: Singapore | E36: Shaw Centre / Scotts Road | F36: 1 Scotts Rd, #03-07 Shaw Centre, Singapore 228208 | G36: +65 8228 7013 | H36: Daily 11:30-15:00, 18:00-22:00 | I36: - | J36: Hana set approx. S$138++ | K36: @sushijin_sg | L36: 8-course omakase; karatsuki uni (summer); braised abalone | M36: 4.4 | N36: Curated (verified) | O36: 1-for-1 promotion on the earliest 17:30 seating. Books out weeks ahead.
A37: 36 | B37: Japanese - Sushi Omakase | C37: Sushi Kimura Plus | D37: Singapore | E37: Cuscaden Road / Conrad Singapore | F37: 1 Cuscaden Rd, #01-03 Conrad, Singapore 249715 | G37: +65 8977 5027 | H37: Tue-Sun, lunch 12:30-14:30 and dinner 19:00-21:30 (varies by day); Mon closed | I37: Chef held one MICHELIN star at previous restaurant | J37: S$380 dinner set | K37: - | L37: Spear-hunted fish; Yura uni; ankimo | M37: 4.7 | N37: Curated (verified) | O37: Chef Tomoo Kimura's return after the original Sushi Kimura at Palais Renaissance closed in 2024. Eight seats, every piece made by the chef himself. Rice recipe now less sweet.
A38: 37 | B38: Japanese - Sushi Omakase | C38: Sushi Maru | D38: Singapore | E38: - | F38: - | G38: - | H38: - | I38: - | J38: - | K38: - | L38: - | N38: Omakase Diaries (Google Drive) | O38: From the 'Omakase Diaries' folder in Google Drive (one subfolder per meal). Country and food type were inferred from the folder name; details not verified unless shown.
A39: 38 | B39: Japanese - Sushi Omakase | C39: Sushi Masa by Ki-setsu | D39: Singapore | E39: Cuppage Plaza / Orchard | F39: 5 Koek Rd, #06-03 Cuppage Plaza, Singapore 228796 | G39: +65 9752 5851 | H39: Tue-Sat 19:00-22:00; Sun-Mon closed | I39: Widely rated among Singapore's best value counters | J39: From S$230 (Hotaru, 16+ courses) | K39: - | L39: Anago; negitoro monaka; otoro aburi; add-on scallop | M39: 4.9 | N39: Curated (verified) | O39: Eight seats, hidden inside an ageing Orchard mall. The 'Hiseki' menu is private bookings or Sundays only, roughly three weeks' notice.
A40: 39 | B40: Japanese - Sushi Omakase | C40: Sushi Masaaki | D40: Singapore | E40: South Beach Avenue / Beach Road | F40: 26 Beach Rd, B1-17 South Beach Avenue, Singapore 189768 | G40: +65 6388 1555 | H40: Daily 12:00-15:00, 18:00-23:00 | I40: - | J40: Lunch from S$220; dinner from S$280 | K40: - | L40: Signature towering Uni Cake; chutoro; nodoguro | M40: 4.7 | N40: Curated (verified) | O40: Kyoto-born Chef Masaaki Sakashita, ex-Sushi Ishi. Fish flown in from Toyosu. Live crabs on the charcoal hearth.
...

Sheet SG · Noodles & Hawker
A1: # | B1: Food Type Category | C1: Name | D1: City / State | E1: Area / Location | F1: Address | G1: Phone | H1: Typical Hours | I1: Accolades | J1: Price Guide (per pax) | K1: Instagram / Web | L1: What To Order / Signature | M1: Google Rating | N1: Source | O1: Notes
A2: 1 | B2: SG Fried Kway Teow & Hokkien Mee | C2: Lao Fu Zi Fried Kway Teow | D2: Singapore | E2: - | F2: - | G2: - | H2: - | I2: MICHELIN Bib Gourmand 2026 | J2: - | K2: - | L2: - | N2: MICHELIN / web guides (Jul 2026) | O2: MICHELIN Guide Singapore Bib Gourmand 2026 (97 establishments). Category inferred from the establishment name; address, phone and hours not yet verified.
A3: 2 | B3: SG Fried Kway Teow & Hokkien Mee | C3: Nam Sing Hokkien Fried Mee | D3: Singapore | E3: Old Airport Road | F3: - | G3: - | H3: - | I3: MICHELIN Bib Gourmand 2026 | J3: - | K3: - | L3: - | N3: MICHELIN / web guides (Jul 2026) | O3: MICHELIN Guide Singapore Bib Gourmand 2026 (97 establishments). Category inferred from the establishment name; address, phone and hours not yet verified.
A4: 3 | B4: SG Fried Kway Teow & Hokkien Mee | C4: No.18 Zion Road Fried Kway Teow | D4: Singapore | E4: Zion Road | F4: - | G4: - | H4: - | I4: MICHELIN Bib Gourmand 2026 | J4: - | K4: - | L4: - | N4: MICHELIN / web guides (Jul 2026) | O4: MICHELIN Guide Singapore Bib Gourmand 2026 (97 establishments). Category inferred from the establishment name; address, phone and hours not yet verified.
A5: 4 | B5: SG Fried Kway Teow & Hokkien Mee | C5: Outram Park Fried Kway Teow Mee | D5: Singapore | E5: Hong Lim | F5: - | G5: - | H5: - | I5: MICHELIN Bib Gourmand 2026 | J5: - | K5: - | L5: - | N5: MICHELIN / web guides (Jul 2026) | O5: MICHELIN Guide Singapore Bib Gourmand 2026 (97 establishments). Category inferred from the establishment name; address, phone and hours not yet verified.
A6: 5 | B6: SG Fried Kway Teow & Hokkien Mee | C6: Singapore Fried Hokkien Mee | D6: Singapore | E6: - | F6: - | G6: - | H6: - | I6: MICHELIN Bib Gourmand 2026 | J6: - | K6: - | L6: - | N6: MICHELIN / web guides (Jul 2026) | O6: MICHELIN Guide Singapore Bib Gourmand 2026 (97 establishments). Category inferred from the establishment name; address, phone and hours not yet verified.
A7: 6 | B7: SG Fried Kway Teow & Hokkien Mee | C7: Wok Hei Hor Fun | D7: Singapore | E7: - | F7: - | G7: - | H7: - | I7: MICHELIN Bib Gourmand 2026 | J7: - | K7: - | L7: - | N7: MICHELIN / web guides (Jul 2026) | O7: MICHELIN Guide Singapore Bib Gourmand 2026 (97 establishments). Category inferred from the establishment name; address, phone and hours not yet verified.
A8: 7 | B8: SG Hawker - Other | C8: Albert Food Centre | D8: Singapore | E8: - | F8: - | G8: - | H8: - | I8: - | J8: - | K8: - | L8: - | N8: Omakase Diaries (Google Drive) | O8: From the 'Omakase Diaries' folder in Google Drive (one subfolder per meal). Country and food type were inferred from the folder name; details not verified unless shown.
A9: 8 | B9: SG Hawker - Other | C9: Heng | D9: Singapore | E9: - | F9: - | G9: - | H9: - | I9: MICHELIN Bib Gourmand 2026 | J9: - | K9: - | L9: - | N9: MICHELIN / web guides (Jul 2026) | O9: MICHELIN Guide Singapore Bib Gourmand 2026 (97 establishments). Category inferred from the establishment name; address, phone and hours not yet verified.
A10: 9 | B10: SG Hawker - Other | C10: Jia Xiang | D10: Singapore | E10: - | F10: - | G10: - | H10: - | I10: MICHELIN Bib Gourmand 2026 - NEW 2026 | J10: - | K10: - | L10: - | N10: MICHELIN / web guides (Jul 2026) | O10: MICHELIN Guide Singapore Bib Gourmand 2026 (97 establishments). Category inferred from the establishment name; address, phone and hours not yet verified.
A11: 10 | B11: SG Hawker - Other | C11: Quan Ji, Amoy Street Food Centre | D11: Singapore | E11: - | F11: - | G11: - | H11: - | I11: - | J11: - | K11: - | L11: - | N11: Omakase Diaries (Google Drive) | O11: From the 'Omakase Diaries' folder in Google Drive (one subfolder per meal). Country and food type were inferred from the folder name; details not verified unless shown.
A12: 11 | B12: SG Hawker - Other | C12: Shunfu Market (Lay Heng, Quan Ann) | D12: Singapore | E12: - | F12: - | G12: - | H12: - | I12: - | J12: - | K12: - | L12: - | N12: Omakase Diaries (Google Drive) | O12: From the 'Omakase Diaries' folder in Google Drive (one subfolder per meal). Country and food type were inferred from the folder name; details not verified unless shown.
A13: 12 | B13: SG Hawker - Other | C13: Xiangyee | D13: Singapore | E13: - | F13: - | G13: - | H13: - | I13: MICHELIN Bib Gourmand 2026 - NEW 2026 | J13: - | K13: - | L13: - | N13: MICHELIN / web guides (Jul 2026) | O13: MICHELIN Guide Singapore Bib Gourmand 2026 (97 establishments). Category inferred from the establishment name; address, phone and hours not yet verified.
... A34: 33 | B34: SG Noodles - Wanton Mee | C34: Yong Chun Wan Ton Noodle | D34: Singapore | E34: - | F34: - | G34: - | H34: - | I34: MICHELIN Bib Gourmand 2026 | J34: - | K34: - | L34: - | N34: MICHELIN / web guides (Jul 2026) | O34: MICHELIN Guide Singapore Bib Gourmand 2026 (97 establishments). Category inferred from the establishment name; address, phone and hours not yet verified.

Sheet SG · Rice, Soup & Porridge
A1: # | B1: Food Type Category | C1: Name | D1: City / State | E1: Area / Location | F1: Address | G1: Phone | H1: Typical Hours | I1: Accolades | J1: Price Guide (per pax) | K1: Instagram / Web | L1: What To Order / Signature | M1: Google Rating | N1: Source | O1: Notes
A2: 1 | B2: SG Bak Kut Teh | C2: Joo Siah Bak Koot Teh | D2: Singapore | E2: - | F2: - | G2: - | H2: - | I2: MICHELIN Bib Gourmand 2026 | J2: - | K2: - | L2: - | N2: MICHELIN / web guides (Jul 2026) | O2: MICHELIN Guide Singapore Bib Gourmand 2026 (97 establishments). Category inferred from the establishment name; address, phone and hours not yet verified.
A3: 2 | B3: SG Bak Kut Teh | C3: Sin Heng Claypot Bak Koot Teh | D3: Singapore | E3: - | F3: - | G3: - | H3: - | I3: MICHELIN Bib Gourmand 2026 | J3: - | K3: - | L3: - | N3: MICHELIN / web guides (Jul 2026) | O3: MICHELIN Guide Singapore Bib Gourmand 2026 (97 establishments). Category inferred from the establishment name; address, phone and hours not yet verified.
A4: 3 | B4: SG Bak Kut Teh | C4: Song Fa Bak Kut Teh (New Bridge Road) | D4: Singapore | E4: New Bridge Road | F4: - | G4: - | H4: - | I4: MICHELIN Bib Gourmand 2026 - 10-edition stalwart | J4: - | K4: - | L4: - | N4: MICHELIN / web guides (Jul 2026) | O4: MICHELIN Guide Singapore Bib Gourmand 2026 (97 establishments). Category inferred from the establishment name; address, phone and hours not yet verified.
A5: 4 | B5: SG Bak Kut Teh | C5: Song Fa Signatures, Paragon | D5: Singapore | E5: - | F5: - | G5: - | H5: - | I5: - | J5: - | K5: - | L5: - | N5: Omakase Diaries (Google Drive) | O5: From the 'Omakase Diaries' folder in Google Drive (one subfolder per meal). Country and food type were inferred from the folder name; details not verified unless shown.
A6: 5 | B6: SG Chicken Rice | C6: Boon Tong Kee (Balestier Road) | D6: Singapore | E6: Balestier Road | F6: - | G6: - | H6: - | I6: MICHELIN Bib Gourmand 2026 | J6: - | K6: - | L6: - | N6: MICHELIN / web guides (Jul 2026) | O6: MICHELIN Guide Singapore Bib Gourmand 2026 (97 establishments). Category inferred from the establishment name; address, phone and hours not yet verified.
A7: 6 | B7: SG Chicken Rice | C7: Hai Nan Zai | D7: Singapore | E7: - | F7: - | G7: - | H7: - | I7: MICHELIN Bib Gourmand 2026 | J7: - | K7: - | L7: - | N7: MICHELIN / web guides (Jul 2026) | O7: MICHELIN Guide Singapore Bib Gourmand 2026 (97 establishments). Category inferred from the establishment name; address, phone and hours not yet verified.
A8: 7 | B8: SG Chicken Rice | C8: Ji De Lai Hainanese Chicken Rice | D8: Singapore | E8: - | F8: - | G8: - | H8: - | I8: MICHELIN Bib Gourmand 2026 | J8: - | K8: - | L8: - | N8: MICHELIN / web guides (Jul 2026) | O8: MICHELIN Guide Singapore Bib Gourmand 2026 (97 establishments). Category inferred from the establishment name; address, phone and hours not yet verified.
A9: 8 | B9: SG Chicken Rice | C9: Margaret Drive Sin Kee Chicken Rice | D9: Singapore | E9: Margaret Drive | F9: - | G9: - | H9: - | I9: MICHELIN Bib Gourmand 2026 | J9: - | K9: - | L9: - | N9: MICHELIN / web guides (Jul 2026) | O9: MICHELIN Guide Singapore Bib Gourmand 2026 (97 establishments). Category inferred from the establishment name; address, phone and hours not yet verified.
A10: 9 | B10: SG Chicken Rice | C10: Nam Kee Chicken Rice | D10: Singapore | E10: - | F10: - | G10: - | H10: - | I10: - | J10: - | K10: - | L10: - | N10: Omakase Diaries (Google Drive) | O10: From the 'Omakase Diaries' folder in Google Drive (one subfolder per meal). Country and food type were inferred from the folder name; details not verified unless shown.
A11: 10 | B11: SG Chicken Rice | C11: Tian Tian Hainanese Chicken Rice | D11: Singapore | E11: Maxwell Food Centre | F11: - | G11: - | H11: - | I11: MICHELIN Bib Gourmand 2026 - 10-edition stalwart | J11: - | K11: - | L11: - | N11: MICHELIN / web guides (Jul 2026) | O11: MICHELIN Guide Singapore Bib Gourmand 2026 (97 establishments). Category inferred from the establishment name; address, phone and hours not yet verified.
A12: 11 | B12: SG Chicken Rice | C12: Tiong Bahru Hainanese Boneless Chicken Rice | D12: Singapore | E12: Tiong Bahru | F12: - | G12: - | H12: - | I12: MICHELIN Bib Gourmand 2026 - 10-edition stalwart | J12: - | K12: - | L12: - | N12: MICHELIN / web guides (Jul 2026) | O12: MICHELIN Guide Singapore Bib Gourmand 2026 (97 establishments). Category inferred from the establishment name; address, phone and hours not yet verified.
A13: 12 | B13: SG Claypot Rice | C13: Lian He Ben Ji Claypot | D13: Singapore | E13: Chinatown Complex | F13: - | G13: - | H13: - | I13: MICHELIN Bib Gourmand 2026 | J13: - | K13: - | L13: - | N13: MICHELIN / web guides (Jul 2026) | O13: MICHELIN Guide Singapore Bib Gourmand 2026 (97 establishments). Category inferred from the establishment name; address, phone and hours not yet verified.
... A39: 38 | B39: SG Yong Tau Foo | C39: Xiu Ji Ikan Bilis Yong Tau Fu | D39: Singapore | E39: Chinatown Complex | F39: - | G39: - | H39: - | I39: MICHELIN Bib Gourmand 2026 - NEW 2026 | J39: - | K39: - | L39: - | N39: MICHELIN / web guides (Jul 2026) | O39: MICHELIN Guide Singapore Bib Gourmand 2026 (97 establishments). Category inferred from the establishment name; address, phone and hours not yet verified.

Sheet SG · Zi Char & Seafood
A1: # | B1: Food Type Category | C1: Name | D1: City / State | E1: Area / Location | F1: Address | G1: Phone | H1: Typical Hours | I1: Accolades | J1: Price Guide (per pax) | K1: Instagram / Web | L1: What To Order / Signature | M1: Google Rating | N1: Source | O1: Notes
A2: 1 | B2: SG Seafood | C2: Alliance Seafood | D2: Singapore | E2: Newton Food Centre | F2: - | G2: - | H2: - | I2: MICHELIN Bib Gourmand 2026 - 10-edition stalwart | J2: - | K2: - | L2: - | N2: MICHELIN / web guides (Jul 2026) | O2: MICHELIN Guide Singapore Bib Gourmand 2026 (97 establishments). Category inferred from the establishment name; address, phone and hours not yet verified.
A3: 2 | B3: SG Seafood | C3: Jumbo Seafood, Dempsey | D3: Singapore | E3: - | F3: - | G3: - | H3: - | I3: - | J3: - | K3: - | L3: - | N3: Omakase Diaries (Google Drive) | O3: From the 'Omakase Diaries' folder in Google Drive (one subfolder per meal). Country and food type were inferred from the folder name; details not verified unless shown.
A4: 3 | B4: SG Seafood | C4: Seafood Paradise, VivoCity | D4: Singapore | E4: - | F4: - | G4: - | H4: - | I4: - | J4: - | K4: - | L4: - | N4: Omakase Diaries (Google Drive) | O4: From the 'Omakase Diaries' folder in Google Drive (one subfolder per meal). Country and food type were inferred from the folder name; details not verified unless shown.
A5: 4 | B5: SG Seafood | C5: Sin Huat Seafood Restaurant | D5: Singapore | E5: Geylang | F5: - | G5: - | H5: - | I5: MICHELIN Bib Gourmand 2026 - 10-edition stalwart | J5: - | K5: - | L5: - | N5: MICHELIN / web guides (Jul 2026) | O5: MICHELIN Guide Singapore Bib Gourmand 2026 (97 establishments). Category inferred from the establishment name; address, phone and hours not yet verified.
A6: 5 | B6: SG Zi Char & Cooked Food | C6: BaShu | D6: Singapore | E6: - | F6: - | G6: - | H6: - | I6: - | J6: - | K6: - | L6: - | N6: Omakase Diaries (Google Drive) | O6: From the 'Omakase Diaries' folder in Google Drive (one subfolder per meal). Country and food type were inferred from the folder name; details not verified unless shown.
A7: 6 | B7: SG Zi Char & Cooked Food | C7: Chamoon Hotpot, Scotts Square | D7: Singapore | E7: - | F7: - | G7: - | H7: - | I7: - | J7: - | K7: - | L7: - | N7: Omakase Diaries (Google Drive) | O7: From the 'Omakase Diaries' folder in Google Drive (one subfolder per meal). Country and food type were inferred from the folder name; details not verified unless shown.
A8: 7 | B8: SG Zi Char & Cooked Food | C8: Crystal Jade | D8: Singapore | E8: - | F8: - | G8: - | H8: - | I8: - | J8: - | K8: - | L8: - | N8: Omakase Diaries (Google Drive) | O8: From the 'Omakase Diaries' folder in Google Drive (one subfolder per meal). Country and food type were inferred from the folder name; details not verified unless shown.
A9: 8 | B9: SG Zi Char & Cooked Food | C9: Dian Xiao Er, Marina Square | D9: Singapore | E9: - | F9: - | G9: - | H9: - | I9: - | J9: - | K9: - | L9: - | N9: Omakase Diaries (Google Drive) | O9: From the 'Omakase Diaries' folder in Google Drive (one subfolder per meal). Country and food type were inferred from the folder name; details not verified unless shown.
A10: 9 | B10: SG Zi Char & Cooked Food | C10: Dudu Cooked Food | D10: Singapore | E10: - | F10: - | G10: - | H10: - | I10: MICHELIN Bib Gourmand 2026 | J10: - | K10: - | L10: - | N10: MICHELIN / web guides (Jul 2026) | O10: MICHELIN Guide Singapore Bib Gourmand 2026 (97 establishments). Category inferred from the establishment name; address, phone and hours not yet verified.
A11: 10 | B11: SG Zi Char & Cooked Food | C11: Eleven Finger (Eu Kee) Scissors Curry Rice | D11: Singapore | E11: - | F11: - | G11: - | H11: - | I11: - | J11: - | K11: - | L11: - | N11: Omakase Diaries (Google Drive) | O11: From the 'Omakase Diaries' folder in Google Drive (one subfolder per meal). Country and food type were inferred from the folder name; details not verified unless shown.
A12: 11 | B12: SG Zi Char & Cooked Food | C12: Fu Ming Cooked Food | D12: Singapore | E12: - | F12: - | G12: - | H12: - | I12: MICHELIN Bib Gourmand 2026 | J12: - | K12: - | L12: - | N12: MICHELIN / web guides (Jul 2026) | O12: MICHELIN Guide Singapore Bib Gourmand 2026 (97 establishments). Category inferred from the establishment name; address, phone and hours not yet verified.
A13: 12 | B13: SG Zi Char & Cooked Food | C13: Hakka Yu, VivoCity | D13: Singapore | E13: - | F13: - | G13: - | H13: - | I13: - | J13: - | K13: - | L13: - | N13: Omakase Diaries (Google Drive) | O13: From the 'Omakase Diaries' folder in Google Drive (one subfolder per meal). Country and food type were inferred from the folder name; details not verified unless shown.
... A35: 34 | B35: SG Zi Char & Cooked Food | C35: Zhup Zhup Noodles | D35: Singapore | E35: - | F35: - | G35: - | H35: - | I35: MICHELIN Bib Gourmand 2026 | J35: - | K35: - | L35: - | N35: MICHELIN / web guides (Jul 2026) | O35: MICHELIN Guide Singapore Bib Gourmand 2026 (97 establishments). Category inferred from the establishment name; address, phone and hours not yet verified.

Sheet SG · Indian, Malay & Peranakan
A1: # | B1: Food Type Category | C1: Name | D1: City / State | E1: Area / Location | F1: Address | G1: Phone | H1: Typical Hours | I1: Accolades | J1: Price Guide (per pax) | K1: Instagram / Web | L1: What To Order / Signature | M1: Google Rating | N1: Source | O1: Notes
A2: 1 | B2: SG Indian | C2: Anglo Indian (Shenton Way) | D2: Singapore | E2: Shenton Way | F2: - | G2: - | H2: - | I2: MICHELIN Bib Gourmand 2026 | J2: - | K2: - | L2: - | N2: MICHELIN / web guides (Jul 2026) | O2: MICHELIN Guide Singapore Bib Gourmand 2026 (97 establishments). Category inferred from the establishment name; address, phone and hours not yet verified.
A3: 2 | B3: SG Indian | C3: Apollo Banana Leaf | D3: Singapore | E3: - | F3: - | G3: - | H3: - | I3: - | J3: - | K3: - | L3: - | N3: Omakase Diaries (Google Drive) | O3: From the 'Omakase Diaries' folder in Google Drive (one subfolder per meal). Country and food type were inferred from the folder name; details not verified unless shown.
A4: 3 | B4: SG Indian | C4: Bismillah Biryani (Little India) | D4: Singapore | E4: Little India | F4: - | G4: - | H4: - | I4: MICHELIN Bib Gourmand 2026 - 10-edition stalwart | J4: - | K4: - | L4: - | N4: MICHELIN / web guides (Jul 2026) | O4: MICHELIN Guide Singapore Bib Gourmand 2026 (97 establishments). Category inferred from the establishment name; address, phone and hours not yet verified.
